Workbook

Sheet FESTIVALS_MASTER
A1: IDENTITY | C1: LOCATION | H1: TIME | L1: DIGITAL PRESENCE | S1: ORGANIZATION | Y1: CULTURAL DOMAINS | AE1: ACCESSIBILITY & SUSTAINABILITY | AH1: METADATA
A2: festival_id | B2: festival_name | C2: city_name | D2: city_geonames_id | E2: region | F2: region_nuts | G2: country_iso | H2: first_edition_year | I2: festival_status | J2: duration_days | K2: recurrence | L2: website_official | M2: website_secondary | N2: website_active | O2: website_languages | P2: instagram | Q2: facebook | R2: digital_presence_score | S2: organizer_type | T2: has_documented_public_funding | U2: has_international_call | V2: has_international_partners | W2: has_international_orientation | X2: has_photography | Y2: has_other_visual_arts | Z2: has_books_press | AA2: has_heritage | AB2: has_architecture_design | AC2: has_performing_arts | AD2: has_audiovisual_multimedia | AE2: venue_type | AF2: ticket_policy | AG2: sustainability_claim | AH2: notes | AI2: record_last_updated
A3: FEST000002 | B3: ANALOGICA | C3: Bolzano | D3: {=XLOOKUP(C3,Locations!A:A,Locations!D:D,"")} -> 3181913 | E3: {=XLOOKUP(C3,Locations!A:A,Locations!E:E,"")} -> Trentino-Alto Adige/Südtirol | F3: {=XLOOKUP(C3,Locations!A:A,Locations!F:F,"")} -> ITH1 | G3: IT | H3: 2011 | I3: active | J3: 5 | K3: annual | L3: https://www.analogica.org/ | M3: null | N3: 1 | O3: IT_EN | P3: https://www.instagram.com/_analogica_/ | Q3: null | R3: {=IF(A3:A6981="","",IF(L3:L6981<>"null",2,0)+IF(N3:N6981=1,2,0)+IF(O3:O6981="IT_EN",1,0)+IF(O3:O6981="MULTI",2,0)+IF(P3:P6981<>"null",2,0)+IF(Q3:Q6981<>"null",2,0))} -> 7 | S3: non-profit | T3: 1 | U3: 1 | V3: 1 | W3: 1 | X3: 1 | Y3: 0 | Z3: 0 | AA3: 1 | AB3: 0 | AC3: 1 | AD3: 1 | AE3: cultural_space | AF3: unknown | AG3: 0 | AI3: 46227
A4: FEST000003 | B4: Milano Centrale Festival | C4: Milano | D4: {=XLOOKUP(C4,Locations!A:A,Locations!D:D,"")} -> 6951411 | E4: {=XLOOKUP(C4,Locations!A:A,Locations!E:E,"")} -> Lombardia | F4: {=XLOOKUP(C4,Locations!A:A,Locations!F:F,"")} -> ITC4 | G4: IT | H4: 2023 | I4: active | J4: 3 | K4: annual | L4: https://www.centralefestival.com/milano2026.html | M4: null | N4: 1 | O4: IT_ONLY | P4: https://www.instagram.com/centralefestival/ | Q4: https://facebook.com/centralefestival/ | R4: 8 | S4: private | T4: 0 | U4: 0 | V4: 0 | W4: 0 | X4: 1 | Y4: 1 | Z4: 1 | AA4: 0 | AB4: 0 | AC4: 1 | AD4: 1 | AE4: mixed | AF4: free | AG4: 0 | AI4: 46227
A5: FEST000004 | B5: Fano Centrale Festival | C5: Fano | D5: {=XLOOKUP(C5,Locations!A:A,Locations!D:D,"")} -> 3177219 | E5: {=XLOOKUP(C5,Locations!A:A,Locations!E:E,"")} -> Marche | F5: {=XLOOKUP(C5,Locations!A:A,Locations!F:F,"")} -> ITI3 | G5: IT | H5: 2009 | I5: active | J5: 7 | K5: annual | L5: https://www.centralefestival.com/fano2027.html | M5: null | N5: 1 | O5: IT_ONLY | P5: https://www.instagram.com/centralefestival/ | Q5: https://facebook.com/centralefestival/ | R5: 8 | S5: non-profit | T5: 1 | U5: 1 | V5: 0 | W5: 1 | X5: 1 | Y5: 1 | Z5: 1 | AA5: 0 | AB5: 0 | AC5: 0 | AD5: 1 | AE5: mixed | AF5: free | AG5: 0 | AI5: 46227
A6: FEST000005 | B6: Festival della Fotografia Etica | C6: Lodi | D6: {=XLOOKUP(C6,Locations!A:A,Locations!D:D,"")} -> 3174638 | E6: {=XLOOKUP(C6,Locations!A:A,Locations!E:E,"")} -> Lombardia | F6: {=XLOOKUP(C6,Locations!A:A,Locations!F:F,"")} -> ITC4 | G6: IT | H6: 2010 | I6: active | J6: 30 | K6: annual | L6: https://www.festivaldellafotografiaetica.it/ | M6: null | N6: 1 | O6: IT_EN | P6: https://www.instagram.com/fotografiaetica/ | Q6: https://www.facebook.com/Festival.della.Fotografia.Etica/ | R6: 9 | S6: non-profit | T6: 1 | U6: 1 | V6: 1 | W6: 1 | X6: 1 | Y6: 0 | Z6: 1 | AA6: 0 | AB6: 0 | AC6: 0 | AD6: 1 | AE6: mixed | AF6: paid | AG6: 1 | AI6: 46227
A7: FEST000006 | B7: Siena Awards Photo Festival | C7: Siena | D7: {=XLOOKUP(C7,Locations!A:A,Locations!D:D,"")} -> 3166548 | E7: {=XLOOKUP(C7,Locations!A:A,Locations!E:E,"")} -> Toscana | F7: {=XLOOKUP(C7,Locations!A:A,Locations!F:F,"")} -> ITI1 | G7: IT | H7: 2015 | I7: active | J7: 51 | K7: annual | L7: https://www.sienawards.com/it/festival | M7: null | N7: 1 | O7: IT_EN | P7: https://www.instagram.com/sienawards/ | Q7: https://www.facebook.com/sipacontest | R7: 9 | S7: non-profit | T7: 0 | U7: 1 | V7: 1 | W7: 1 | X7: 1 | Y7: 0 | Z7: 1 | AA7: 0 | AB7: 0 | AC7: 0 | AD7: 0 | AE7: mixed | AF7: paid | AG7: 0 | AI7: 46227
A8: FEST000008 | B8: Yeast Photo Festival | C8: Matino | D8: {=XLOOKUP(C8,Locations!A:A,Locations!D:D,"")} -> 3173711 | E8: {=XLOOKUP(C8,Locations!A:A,Locations!E:E,"")} -> Puglia | F8: {=XLOOKUP(C8,Locations!A:A,Locations!F:F,"")} -> ITF4 | G8: IT | H8: 2021 | I8: active | J8: 59 | K8: annual | L8: https://www.yeastphotofestival.it/ | M8: null | N8: 1 | O8: IT_EN | P8: https://www.instagram.com/yeastphotofestival/ | Q8: https://www.facebook.com/yeastphotofestival/ | R8: 9 | S8: non-profit | T8: 0 | U8: 1 | V8: 1 | W8: 1 | X8: 1 | Y8: 1 | Z8: 0 | AA8: 0 | AB8: 0 | AC8: 0 | AD8: 0 | AE8: mixed | AF8: unknown | AG8: 1 | AH8: Festival diffuso sul territorio (Salento) | AI8: 46227
A9: FEST000009 | B9: Grenze - Arsenali Fotografici | C9: Verona | D9: {=XLOOKUP(C9,Locations!A:A,Locations!D:D,"")} -> 3164527 | E9: {=XLOOKUP(C9,Locations!A:A,Locations!E:E,"")} -> Veneto | F9: {=XLOOKUP(C9,Locations!A:A,Locations!F:F,"")} -> ITH3 | G9: IT | H9: 2018 | I9: active | J9: 32 | K9: annual | L9: https://www.grenzearsenalifotografici.com/ | M9: null | N9: 1 | O9: IT_EN | P9: https://www.instagram.com/grenze.arsenali.fotografici/?hl=it | Q9: https://www.facebook.com/grenzearsenalifotografici/ | R9: 9 | S9: non-profit | T9: 1 | U9: 1 | V9: 1 | W9: 1 | X9: 1 | Y9: 1 | Z9: 1 | AA9: 0 | AB9: 0 | AC9: 1 | AD9: 0 | AE9: mixed | AF9: unknown | AG9: 0 | AI9: 46227
A10: FEST000011 | B10: SI Fest - Savignano Immagini Festival | C10: Savignano sul Rubicone | D10: {=XLOOKUP(C10,Locations!A:A,Locations!D:D,"")} -> 3167030 | E10: {=XLOOKUP(C10,Locations!A:A,Locations!E:E,"")} -> Emilia-Romagna | F10: {=XLOOKUP(C10,Locations!A:A,Locations!F:F,"")} -> ITH5 | G10: IT | H10: 1992 | I10: active | J10: 17 | K10: annual | L10: https://www.sifest.it/ | M10: null | N10: 1 | O10: IT_ONLY | P10: https://www.instagram.com/sifest/ | Q10: https://www.facebook.com/savignano.immagini | R10: 8 | S10: non-profit | T10: 1 | U10: 1 | V10: 0 | W10: 1 | X10: 1 | Y10: 1 | Z10: 1 | AA10: 0 | AB10: 0 | AC10: 1 | AD10: 1 | AE10: mixed | AF10: unknown | AG10: 0 | AI10: 46227
A11: FEST000012 | B11: ZeroNegativo | C11: Santeramo in Colle | D11: {=XLOOKUP(C11,Locations!A:A,Locations!D:D,"")} -> 3167327 | E11: {=XLOOKUP(C11,Locations!A:A,Locations!E:E,"")} -> Puglia | F11: {=XLOOKUP(C11,Locations!A:A,Locations!F:F,"")} -> ITF4 | G11: IT | H11: 2024 | I11: active | J11: 4 | K11: annual | L11: https://zeronegativofest.it/ | M11: null | N11: 1 | O11: IT_ONLY | P11: https://www.instagram.com/zeronegativofest/ | Q11: https://www.facebook.com/p/Zeronegativo-61573755717554/ | R11: 8 | S11: non-profit | T11: 1 | U11: 0 | V11: 0 | W11: 1 | X11: 1 | Y11: 1 | Z11: 1 | AA11: 0 | AB11: 1 | AC11: 0 | AD11: 1 | AE11: mixed | AF11: unknown | AG11: 1 | AH11: Festival itinerante tra Puglia e Toscana | AI11: 46227
A12: FEST000013 | B12: Festival Ubiqua | C12: Cinisello Balsamo | D12: {=XLOOKUP(C12,Locations!A:A,Locations!D:D,"")} -> 3178671 | E12: {=XLOOKUP(C12,Locations!A:A,Locations!E:E,"")} -> Lombardia | F12: {=XLOOKUP(C12,Locations!A:A,Locations!F:F,"")} -> ITC4 | G12: IT | H12: 2022 | I12: active | J12: 4 | K12: annual | L12: null | M12: https://munaf.it/ubiqua/ | N12: 0 | O12: IT_ONLY | P12: null | Q12: null | R12: 0 | S12: public | T12: 0 | U12: 0 | V12: 0 | W12: 0 | X12: 1 | Y12: 1 | Z12: 1 | AA12: 1 | AB12: 0 | AC12: 1 | AD12: 1 | AE12: historic_site | AF12: free | AG12: 0 | AI12: 46227
A13: FEST000014 | B13: Treviso Photographic Festival | C13: Treviso | D13: {=XLOOKUP(C13,Locations!A:A,Locations!D:D,"")} -> 3165201 | E13: {=XLOOKUP(C13,Locations!A:A,Locations!E:E,"")} -> Veneto | F13: {=XLOOKUP(C13,Locations!A:A,Locations!F:F,"")} -> ITH3 | G13: IT | H13: 2018 | I13: active | J13: 22 | K13: annual | L13: https://www.trevisophotographicfestival.it/ | M13: null | N13: 1 | O13: IT_EN | P13: https://www.instagram.com/trevisophotographicfestival/ | Q13: https://www.facebook.com/lab77associazione/ | R13: 9 | S13: non-profit | T13: 0 | U13: 0 | V13: 1 | W13: 1 | X13: 1 | Y13: 0 | Z13: 0 | AA13: 1 | AB13: 0 | AC13: 1 | AD13: 0 | AE13: public_space | AF13: unknown | AG13: 0 | AI13: 46227
A14: FEST000015 | B14: Ragusa Foto Festival | C14: Ragusa | D14: {=XLOOKUP(C14,Locations!A:A,Locations!D:D,"")} -> 2523650 | E14: {=XLOOKUP(C14,Locations!A:A,Locations!E:E,"")} -> Sicilia | F14: {=XLOOKUP(C14,Locations!A:A,Locations!F:F,"")} -> ITG1 | G14: IT | H14: 2012 | I14: active | J14: 32 | K14: annual | L14: https://www.ragusafotofestival.com/ | M14: null | N14: 1 | O14: IT_ONLY | P14: https://www.instagram.com/ragusa_fotofestival | Q14: https://www.facebook.com/ragusafotofestival | R14: 8 | S14: non-profit | T14: 1 | U14: 1 | V14: 1 | W14: 1 | X14: 1 | Y14: 1 | Z14: 1 | AA14: 1 | AB14: 0 | AC14: 0 | AD14: 0 | AE14: mixed | AF14: paid | AG14: 0 | AI14: 46227
A15: FEST000017 | B15: PhEst – Festival Internazionale di Fotografia e Arte | C15: Monopoli | D15: {=XLOOKUP(C15,Locations!A:A,Locations!D:D,"")} -> 3173131 | E15: {=XLOOKUP(C15,Locations!A:A,Locations!E:E,"")} -> Puglia | F15: {=XLOOKUP(C15,Locations!A:A,Locations!F:F,"")} -> ITF4 | G15: IT | H15: 2016 | I15: active | J15: 101 | K15: annual | L15: https://www.phest.info/ | M15: null | N15: 1 | O15: IT_EN | P15: https://www.instagram.com/_phest_ | Q15: https://www.facebook.com/PhESTSeeBeyondTheSea/ | R15: 9 | S15: non-profit | T15: 1 | W15: 1 | X15: 1 | Y15: 1 | Z15: 1 | AA15: 1 | AB15: 1 | AC15: 1 | AD15: 1 | AE15: mixed | AF15: paid | AG15: 0 | AI15: 46227
A16: FEST000018 | B16: Fotografia Calabria Festival | C16: San Lucido | D16: {=XLOOKUP(C16,Locations!A:A,Locations!D:D,"")} -> 2523435 | E16: {=XLOOKUP(C16,Locations!A:A,Locations!E:E,"")} -> Calabria | F16: {=XLOOKUP(C16,Locations!A:A,Locations!F:F,"")} -> ITF6 | G16: IT | H16: 2022 | I16: active | J16: 12 | K16: annual | L16: https://www.fotografiacalabriafestival.it/ | M16: null | N16: 1 | O16: IT_EN | P16: https://www.instagram.com/fotografiacalabriafestival?igsh=ZXh4NDd6aGdmNHZq | Q16: https://www.facebook.com/fotografiacalabriafestival | R16: 9 | S16: non-profit | T16: 1 | U16: 1 | V16: 0 | W16: 1 | X16: 1 | Y16: 0 | Z16: 1 | AA16: 1 | AB16: 1 | AC16: 0 | AD16: 0 | AE16: public_space | AF16: mixed | AG16: 0 | AI16: 46227
A17: FEST000021 | B17: Cortona On The Move | C17: Cortona | D17: {=XLOOKUP(C17,Locations!A:A,Locations!D:D,"")} -> 3177948 | E17: {=XLOOKUP(C17,Locations!A:A,Locations!E:E,"")} -> Toscana | F17: {=XLOOKUP(C17,Locations!A:A,Locations!F:F,"")} -> ITI1 | G17: IT | H17: 2011 | I17: active | J17: 108 | K17: annual | L17: https://www.cortonaonthemove.com/ | M17: null | N17: 1 | O17: IT_EN | P17: https://www.instagram.com/cortonaonthemove/ | Q17: https://www.facebook.com/festivalcortonaonthemove | R17: 9 | S17: non-profit | T17: 1 | U17: 1 | V17: 1 | X17: 1 | Y17: 0 | Z17: 1 | AB17: 0 | AC17: 0 | AD17: 1 | AE17: mixed | AF17: paid | AG17: 0
A18: FEST000024 | B18: Langhe Photo Festival | C18: Neive | D18: {=XLOOKUP(C18,Locations!A:A,Locations!D:D,"")} -> 6536417 | E18: {=XLOOKUP(C18,Locations!A:A,Locations!E:E,"")} -> Piemonte | F18: {=XLOOKUP(C18,Locations!A:A,Locations!F:F,"")} -> ITC1 | G18: IT | H18: 2023 | I18: inactive | J18: 119 | K18: annual | L18: https://langhephotofestival.com/ | M18: null | N18: 0 | O18: IT_ONLY | P18: https://www.instagram.com/langhephotofestival/ | Q18: https://www.facebook.com/LanghePhotoFestival/ | R18: 6 | S18: non-profit | T18: 1 | U18: 0 | V18: 0 | X18: 1 | Y18: 0 | Z18: 1 | AB18: 0 | AC18: 0 | AD18: 0 | AE18: mixed | AF18: paid | AG18: 0
A19: FEST000025 | B19: Festival del Reportage | C19: Ascoli Piceno | D19: {=XLOOKUP(C19,Locations!A:A,Locations!D:D,"")} -> 3182749 | E19: {=XLOOKUP(C19,Locations!A:A,Locations!E:E,"")} -> Marche | F19: {=XLOOKUP(C19,Locations!A:A,Locations!F:F,"")} -> ITI3 | G19: IT | H19: 2021 | I19: active | J19: 3 | K19: annual | L19: https://www.festivaldelreportage.it/ | M19: null | N19: 1 | O19: IT_ONLY | P19: https://www.instagram.com/festivaldelreportage/ | Q19: https://www.facebook.com/festivaldelreportage | R19: 8 | S19: non-profit | T19: 0 | U19: 0 | V19: 0 | X19: 1 | Y19: 0 | Z19: 1 | AB19: 0 | AC19: 0 | AD19: 1 | AE19: mixed | AF19: paid | AG19: 0
A20: FEST000026 | B20: Flaiano fO - Festival Internazionale di Fotografia e Giornalismo | C20: Pescara | D20: {=XLOOKUP(C20,Locations!A:A,Locations!D:D,"")} -> 3171168 | E20: {=XLOOKUP(C20,Locations!A:A,Locations!E:E,"")} -> Abruzzo | F20: {=XLOOKUP(C20,Locations!A:A,Locations!F:F,"")} -> ITF1 | G20: IT | H20: 2023 | I20: inactive | J20: 2 | K20: annual | L20: null | M20: https://www.premiflaiano.com/ | N20: 0 | O20: IT_EN | P20: null | Q20: null | R20: 1 | S20: non-profit | T20: 0 | U20: 0 | V20: 0 | W20: 1 | X20: 1 | Y20: 0 | Z20: 1 | AA20: 0 | AB20: 1 | AC20: 0 | AD20: 1 | AE20: cultural_space | AF20: free | AG20: 0
A21: FEST000027 | B21: GU.PHO. Photo Festival Internazionale Vernacolare | C21: Guiglia | D21: {=XLOOKUP(C21,Locations!A:A,Locations!D:D,"")} -> 3175676 | E21: {=XLOOKUP(C21,Locations!A:A,Locations!E:E,"")} -> Emilia-Romagna | F21: {=XLOOKUP(C21,Locations!A:A,Locations!F:F,"")} -> ITH5 | G21: IT | H21: 2022 | I21: active | J21: 9 | K21: annual | L21: https://gupho.art/ | M21: null | N21: 1 | O21: IT_EN | P21: https://www.instagram.com/gu.pho.festival/ | Q21: https://www.facebook.com/Gu.Pho.Festival/?locale=it_IT | R21: 9 | S21: non-profit | T21: 1 | U21: 0 | V21: 0 | X21: 1 | Y21: 0 | Z21: 1 | AB21: 0 | AC21: 0 | AD21: 1 | AE21: historic_site | AF21: free | AG21: 0
A22: FEST000028 | B22: Festival della Fotografia Italiana | C22: Bibbiena | D22: {=XLOOKUP(C22,Locations!A:A,Locations!D:D,"")} -> 3182059 | E22: {=XLOOKUP(C22,Locations!A:A,Locations!E:E,"")} -> Toscana | F22: {=XLOOKUP(C22,Locations!A:A,Locations!F:F,"")} -> ITI1 | G22: IT | H22: 2024 | I22: active | J22: 87 | K22: annual | L22: https://www.festivalfotografiaitaliana.it/ | M22: null | N22: 1 | O22: IT_ONLY | P22: https://www.instagram.com/insta.fiaf/ | Q22: https://www.facebook.com/fiaf.net | R22: 8 | S22: non-profit | T22: 1 | U22: 0 | V22: 0 | X22: 1 | Y22: 0 | Z22: 1 | AB22: 0 | AC22: 0 | AD22: 0 | AE22: mixed | AF22: mixed | AG22: 0
A23: FEST000029 | B23: Le Giornate della Luce | C23: Spilimbergo | D23: {=XLOOKUP(C23,Locations!A:A,Locations!D:D,"")} -> 3166262 | E23: {=XLOOKUP(C23,Locations!A:A,Locations!E:E,"")} -> Friuli-Venezia Giulia | F23: {=XLOOKUP(C23,Locations!A:A,Locations!F:F,"")} -> ITH4 | G23: IT | H23: 2015 | I23: active | J23: 9 | K23: annual | L23: http://www.legiornatedellaluce.it/ | M23: null | N23: 1 | O23: IT_ONLY | P23: https://www.instagram.com/legiornatedellaluce/ | Q23: https://www.facebook.com/legiornatedellaluce/?locale=it_IT | R23: 8 | S23: non-profit | T23: 1 | U23: 0 | V23: 1 | X23: 1 | Y23: 0 | Z23: 1 | AB23: 0 | AC23: 0 | AD23: 1 | AE23: mixed | AF23: mixed | AG23: 1
A24: FEST000030 | B24: Asincronie - Festival di Cinema documentario e Fotografia | C24: Sassari | D24: {=XLOOKUP(C24,Locations!A:A,Locations!D:D,"")} -> 3167096 | E24: {=XLOOKUP(C24,Locations!A:A,Locations!E:E,"")} -> Sardegna | F24: {=XLOOKUP(C24,Locations!A:A,Locations!F:F,"")} -> ITG2 | G24: IT | H24: 2020 | I24: active | J24: 32 | K24: annual | L24: https://www.asincronie.net/ | M24: null | N24: 1 | O24: IT_EN | P24: https://www.instagram.com/asincronie_festival/ | Q24: https://www.facebook.com/Asincronie-Festival-di-Cinema-Documentario-e-Fotografia-715947922539789 | R24: 9 | S24: non-profit | T24: 1 | U24: 1 | V24: 1 | X24: 1 | Y24: 0 | Z24: 1 | AB24: 0 | AC24: 1 | AD24: 1 | AE24: mixed | AF24: free | AG24: 0
A25: FEST000031 | B25: Fotografia Europea | C25: Reggio nell'Emilia | D25: {=XLOOKUP(C25,Locations!A:A,Locations!D:D,"")} -> 3169522 | E25: {=XLOOKUP(C25,Locations!A:A,Locations!E:E,"")} -> Emilia-Romagna | F25: {=XLOOKUP(C25,Locations!A:A,Locations!F:F,"")} -> ITH5 | G25: IT | H25: 2006 | I25: active | J25: 46 | K25: annual | L25: https://www.fotografiaeuropea.it/ | M25: null | N25: 1 | O25: IT_EN | P25: https://instagram.com/fotografia_europea/ | Q25: http://www.facebook.com/FotografiaEuropea | R25: 9 | S25: mixed | T25: 1 | U25: 1 | V25: 1 | X25: 1 | Y25: 0 | Z25: 1 | AB25: 0 | AC25: 1 | AD25: 1 | AE25: mixed | AF25: mixed | AG25: 1
A26: FEST000032 | B26: MIA Photo Fair BNP Paribas | C26: Milano | D26: {=XLOOKUP(C26,Locations!A:A,Locations!D:D,"")} -> 6951411 | E26: {=XLOOKUP(C26,Locations!A:A,Locations!E:E,"")} -> Lombardia | F26: {=XLOOKUP(C26,Locations!A:A,Locations!F:F,"")} -> ITC4 | G26: IT | H26: 2011 | I26: active | J26: 4 | K26: annual | L26: https://www.miafairbnpparibas.it/ | M26: null | N26: 1 | O26: IT_EN | P26: https://www.instagram.com/miaphotofair/ | Q26: https://www.facebook.com/miaphotofair/ | R26: 9 | S26: private | T26: 0 | U26: 1 | V26: 1 | X26: 1 | Y26: 1 | Z26: 1 | AB26: 1 | AC26: 0 | AD26: 1 | AE26: cultural_space | AF26: paid | AG26: 0
A27: FEST000033 | B27: Festival Fotografico Europeo | C27: Castellanza | D27: {=XLOOKUP(C27,Locations!A:A,Locations!D:D,"")} -> 3179650 | E27: {=XLOOKUP(C27,Locations!A:A,Locations!E:E,"")} -> Lombardia | F27: {=XLOOKUP(C27,Locations!A:A,Locations!F:F,"")} -> ITC4 | G27: IT | H27: 2013 | I27: active | J27: 50 | K27: annual | L27: https://www.europhotofestival.com/ | M27: null | N27: 1 | O27: IT_ONLY | P27: https://www.instagram.com/archiviofotograficoitaliano/ | Q27: https://www.facebook.com/archiviofotograficoitaliano/ | R27: 8 | S27: non-profit | T27: 1 | U27: 0 | V27: 1 | X27: 1 | Y27: 0 | Z27: 1 | AB27: 0 | AC27: 1 | AD27: 1 | AE27: mixed | AF27: free | AG27: 0 | AH27: Festival diffuso che coinvolge anche Legnano, Castellanza, Olgiate Olona, Cairate e altre sedi del territorio.
A28: FEST000034 | B28: Brescia Photo Festival | C28: Brescia | D28: {=XLOOKUP(C28,Locations!A:A,Locations!D:D,"")} -> 3181554 | E28: {=XLOOKUP(C28,Locations!A:A,Locations!E:E,"")} -> Lombardia | F28: {=XLOOKUP(C28,Locations!A:A,Locations!F:F,"")} -> ITC4 | G28: IT | H28: 2017 | I28: active | J28: 4 | K28: annual | L28: null | M28: https://www.bresciamusei.com/evento/brescia-photo-festival/ | N28: 0 | O28: IT_EN | P28: null | Q28: null | R28: 1 | S28: mixed | T28: 1 | U28: 0 | V28: 1 | X28: 1 | Y28: 0 | Z28: 1 | AB28: 0 | AC28: 0 | AD28: 1 | AE28: mixed | AF28: mixed | AG28: 0 | AH28: Il festival disponeva in passato di una presenza web autonoma; attualmente la comunicazione è integrata nei canali istituzionali di Fondazione Brescia Musei e Comune di Brescia. Non risultano profili social dedicati al festival, ma solo canali degli enti promotori.
A29: FEST000035 | B29: Photolux Festival | C29: Lucca | D29: {=XLOOKUP(C29,Locations!A:A,Locations!D:D,"")} -> 3174530 | E29: {=XLOOKUP(C29,Locations!A:A,Locations!E:E,"")} -> Toscana | F29: {=XLOOKUP(C29,Locations!A:A,Locations!F:F,"")} -> ITI1 | G29: IT | H29: 2005 | I29: active | J29: 51 | K29: biennial | L29: https://www.photoluxfestival.it/ | M29: null | N29: 0 | O29: IT_EN | P29: https://www.instagram.com/photoluxfest/ | Q29: https://www.facebook.com/PhotoluxFestival | R29: 7 | S29: non-profit | T29: 1 | U29: 0 | V29: 1 | X29: 1 | Y29: 0 | Z29: 1 | AB29: 0 | AC29: 0 | AD29: 0 | AE29: mixed | AF29: paid | AG29: 0 | AH29: Continuità storica con Lucca Photo Fest (2005); il brand Photolux Festival nasce nel 2012.
A30: FEST000036 | B30: Ricarica Foto Festival | C30: Sustinente | D30: {=XLOOKUP(C30,Locations!A:A,Locations!D:D,"")} -> 3166011 | E30: {=XLOOKUP(C30,Locations!A:A,Locations!E:E,"")} -> Lombardia | F30: {=XLOOKUP(C30,Locations!A:A,Locations!F:F,"")} -> ITC4 | G30: IT | H30: 2022 | I30: defunct | J30: 17 | K30: biennial | L30: https://ricaricafotofestival.it/home-page/ | M30: null | N30: 0 | O30: IT_ONLY | P30: null | Q30: null | R30: 2 | S30: non-profit | U30: 0 | V30: 0 | X30: 1 | Y30: 1 | Z30: 1 | AB30: 0 | AC30: 0 | AD30: 1 | AE30: mixed | AF30: paid | AG30: 1 | AH30: Ricarica Foto Festival concluso come format autonomo dopo l'edizione 2024; evoluto nel progetto BASC – Biennale d’Arte Sociale e di Comunità.
A31: FEST000037 | B31: Biennale della Fotografia Femminile | C31: Mantova | D31: {=XLOOKUP(C31,Locations!A:A,Locations!D:D,"")} -> 3174051 | E31: {=XLOOKUP(C31,Locations!A:A,Locations!E:E,"")} -> Lombardia | F31: {=XLOOKUP(C31,Locations!A:A,Locations!F:F,"")} -> ITC4 | G31: IT | H31: 2020 | I31: active | J31: 24 | K31: biennial | L31: https://www.bffmantova.com/ | M31: null | N31: 1 | O31: IT_EN | P31: https://www.instagram.com/bffmantova/ | Q31: https://www.facebook.com/bffmantova | R31: 9 | S31: non-profit | T31: 1 | U31: 1 | V31: 1 | X31: 1 | Y31: 0 | Z31: 1 | AB31: 0 | AC31: 0 | AD31: 1 | AE31: cultural_space | AF31: mixed | AG31: 0
A32: FEST000038 | B32: Milano Photofestival | C32: Milano | D32: {=XLOOKUP(C32,Locations!A:A,Locations!D:D,"")} -> 6951411 | E32: {=XLOOKUP(C32,Locations!A:A,Locations!E:E,"")} -> Lombardia | F32: {=XLOOKUP(C32,Locations!A:A,Locations!F:F,"")} -> ITC4 | G32: IT | H32: 2005 | I32: inactive | J32: 47 | K32: annual | L32: http://www.milanophotofestival.it/ | M32: null | N32: 0 | O32: IT_EN | P32: https://www.instagram.com/milanophotofestival/ | Q32: https://www.facebook.com/photofestivalmilano/ | R32: 7 | S32: non-profit | T32: 1 | U32: 0 | V32: 0 | X32: 1 | Y32: 0 | Z32: 1 | AB32: 0 | AC32: 0 | AD32: 1 | AE32: mixed | AF32: free | AG32: 1
A33: FEST000039 | B33: Umbria World Fest | C33: Foligno | D33: {=XLOOKUP(C33,Locations!A:A,Locations!D:D,"")} -> 3176854 | E33: {=XLOOKUP(C33,Locations!A:A,Locations!E:E,"")} -> Umbria | F33: {=XLOOKUP(C33,Locations!A:A,Locations!F:F,"")} -> ITI2 | G33: IT | H33: unknown | I33: inactive | J33: 3 | K33: annual | L33: http://www.umbriaworldfest.it/ | M33: null | N33: 0 | O33: IT_EN | P33: https://www.instagram.com/umbriaworldfest/ | Q33: https://www.facebook.com/UmbriaWorldFest/ | R33: 7 | S33: non-profit | T33: 1 | U33: 0 | V33: 0 | X33: 1 | Y33: 0 | Z33: 1 | AB33: 0 | AC33: 1 | AD33: 1 | AE33: mixed | AF33: mixed | AG33: 0
A34: FEST000040 | B34: ImagOrbetello Photo Festival | C34: Orbetello | D34: {=XLOOKUP(C34,Locations!A:A,Locations!D:D,"")} -> 3171985 | E34: {=XLOOKUP(C34,Locations!A:A,Locations!E:E,"")} -> Toscana | F34: {=XLOOKUP(C34,Locations!A:A,Locations!F:F,"")} -> ITI1 | G34: IT | H34: 2013 | I34: inactive | J34: unknown | K34: annual | L34: https://www.imagorbetello.com/ | M34: null | N34: 0 | O34: IT_ONLY | P34: https://www.instagram.com/imago.photofestival/ | Q34: https://www.facebook.com/ImagOrbetello | R34: 6 | S34: non-profit | T34: 1 | U34: 1 | V34: 1 | X34: 1 | Y34: 0 | Z34: 1 | AB34: 0 | AC34: 0 | AD34: 1 | AE34: mixed | AF34: free | AG34: 0
A35: FEST000041 | B35: CHARTA: a Photobook Festival | C35: Roma | D35: {=XLOOKUP(C35,Locations!A:A,Locations!D:D,"")} -> 8957247 | E35: {=XLOOKUP(C35,Locations!A:A,Locations!E:E,"")} -> Lazio | F35: {=XLOOKUP(C35,Locations!A:A,Locations!F:F,"")} -> ITI4 | G35: IT | H35: 2021 | I35: active | J35: 9 | K35: biennial | L35: https://chartafestival.com/it/ | M35: null | N35: 1 | O35: IT_EN | P35: https://www.instagram.com/chartafestival/?hl=it | Q35: https://www.facebook.com/ChartaFestival/ | R35: 9 | S35: non-profit | T35: 1 | U35: 1 | V35: 1 | X35: 1 | Y35: 0 | Z35: 1 | AB35: 0 | AC35: 0 | AD35: 0 | AE35: cultural_space | AF35: free | AG35: 0
A36: FEST000042 | B36: Molichrom: Festical della Fotografia Nomade | C36: Campobasso | D36: {=XLOOKUP(C36,Locations!A:A,Locations!D:D,"")} -> 3180991 | E36: {=XLOOKUP(C36,Locations!A:A,Locations!E:E,"")} -> Molise | F36: {=XLOOKUP(C36,Locations!A:A,Locations!F:F,"")} -> ITF2 | G36: IT | H36: 2022 | I36: active | J36: 47 | K36: annual | L36: https://www.molichrom.com/ | M36: null | N36: 1 | O36: IT_ONLY | P36: https://www.instagram.com/molichrom_festival | Q36: https://www.facebook.com/molichrom | R36: 8 | S36: non-profit | T36: 1 | U36: 0 | V36: 0 | X36: 1 | Y36: 0 | Z36: 1 | AB36: 0 | AC36: 0 | AD36: 1 | AE36: mixed | AF36: mixed | AG36: 0
A37: FEST000043 | B37: PhotoVogue Festival | C37: Milano | D37: {=XLOOKUP(C37,Locations!A:A,Locations!D:D,"")} -> 6951411 | E37: {=XLOOKUP(C37,Locations!A:A,Locations!E:E,"")} -> Lombardia | F37: {=XLOOKUP(C37,Locations!A:A,Locations!F:F,"")} -> ITC4 | G37: IT | H37: 2016 | I37: active | J37: 4 | K37: annual | L37: null | M37: https://www.vogue.it/article/photovogue-festival-2026-programma-cosa-sapere-location | N37: 0 | O37: IT_ONLY | P37: https://www.instagram.com/photovogue/ | Q37: null | R37: 2 | S37: private | T37: 0 | U37: 1 | V37: 1 | X37: 1 | Y37: 1 | Z37: 0 | AB37: 0 | AC37: 0 | AD37: 1 | AE37: cultural_space | AF37: free | AG37: 0
A38: FEST000044 | B38: Liquida Photofestival | C38: Torino | D38: {=XLOOKUP(C38,Locations!A:A,Locations!D:D,"")} -> 8980539 | E38: {=XLOOKUP(C38,Locations!A:A,Locations!E:E,"")} -> Piemonte | F38: {=XLOOKUP(C38,Locations!A:A,Locations!F:F,"")} -> ITC1 | G38: IT | H38: 2022 | I38: active | J38: 3 | K38: annual | L38: null | M38: https://www.paratissima.it/liquida-photofestival-2026/ | N38: 0 | O38: IT_ONLY | P38: https://www.instagram.com/liquidaphotofestival/ | Q38: null | R38: 2 | S38: non-profit | T38: 0 | U38: 1 | V38: 0 | X38: 1 | Y38: 1 | Z38: 1 | AB38: 0 | AC38: 0 | AD38: 0 | AE38: historic_site | AF38: paid | AG38: 0
A39: FEST000045 | B39: Corigliano Calabro Fotografia | C39: Corigliano-Rossano | D39: {=XLOOKUP(C39,Locations!A:A,Locations!D:D,"")} -> 12032199 | E39: {=XLOOKUP(C39,Locations!A:A,Locations!E:E,"")} -> Calabria | F39: {=XLOOKUP(C39,Locations!A:A,Locations!F:F,"")} -> ITF6 | G39: IT | H39: 2003 | I39: active | J39: 58 | K39: annual | L39: https://www.coriglianocalabrofotografia.it/ | N39: 1 | O39: IT_ONLY | P39: https://www.instagram.com/coriglianocalabrofotografia/ | Q39: https://www.facebook.com/coriglianocalabrofotografia/?locale=it_IT | R39: 8 | S39: non-profit | T39: 1 | U39: 0 | V39: 0 | X39: 1 | Y39: 0 | Z39: 1 | AB39: 0 | AC39: 0 | AD39: 0 | AE39: historic_site | AF39: free | AG39: 0
A40: FEST000046 | B40: Festival di Fotografia Montefano Arturo Ghergo | C40: Montefano | D40: {=XLOOKUP(C40,Locations!A:A,Locations!D:D,"")} -> 3172935 | E40: {=XLOOKUP(C40,Locations!A:A,Locations!E:E,"")} -> Marche | F40: {=XLOOKUP(C40,Locations!A:A,Locations!F:F,"")} -> ITI3 | G40: IT | H40: 2015 | I40: active | J40: 3 | K40: annual | L40: https://www.festivalarturoghergo.com/ | N40: 1 | O40: IT_ONLY | P40: https://www.instagram.com/festival_fotografia_montefano | Q40: https://it-it.facebook.com/effettoghergo/ | R40: 8 | S40: non-profit | T40: 1 | U40: 0 | V40: 0 | X40: 1 | Y40: 0 | Z40: 1 | AB40: 0 | AC40: 0 | AD40: 1 | AE40: historic_site | AF40: mixed | AG40: 0
...

Sheet CODEBOOK
A1: class | B1: variable_name | C1: description | D1: data_type | E1: values | F1: coding_rules | G1: source
A2: IDENTITY | B2: festival_id | C2: Identificativo univoco del festival | D2: Stringa | E2: Formato: FEST000001 | F2: Assegnare un identificativo univoco progressivo secondo il formato FEST000001. | G2: -
B3: festival_name | C3: Denominazione ufficiale del festival | D3: Stringa | E3: Testo libero | F3: Utilizzare la denominazione ufficiale del festival; evitare sottotitoli o varianti non costanti tra le fonti. | G3: -
A4: LOCATION | B4: city_name | C4: Comune principale di svolgimento del festival | D4: Stringa | E4: Denominazione ufficiale ISTAT del comune | F4: Inserire esclusivamente il comune principale di svolgimento. Nei casi di festival multi-sede o itineranti utilizzare la sede legale o l'hub organizzativo principale e documentare eventuali eccezioni nella variabile notes. | G4: ISTAT, Codici delle unità amministrative. Aggiornamento al 21 febbraio 2026, 2026, https://www.istat.it/classificazione/codici-dei-comuni-delle-province-e-delle-regioni/ (ultimo accesso luglio 2026).
B5: city_geonames_id | C5: Identificativo GeoNames associato al comune | D5: Intero | E5: Identificativo GeoNames | F5: Associare l'identificativo GeoNames corrispondente al comune selezionato. | G5: GeoNames, GeoNames Data, IT.zip, 2026, https://download.geonames.org/export/dump/ (ultimo accesso luglio 2026).
B6: region | C6: Regione italiana di riferimento del festival | D6: Stringa | E6: Denominazione ufficiale ISTAT della regione | F6: Derivare automaticamente dalla città selezionata utilizzando le denominazioni ufficiali ISTAT. | G6: ISTAT, Codici delle unità amministrative. Aggiornamento al 21 febbraio 2026, 2026, https://www.istat.it/classificazione/codici-dei-comuni-delle-province-e-delle-regioni/ (ultimo accesso luglio 2026).
B7: region_nuts | C7: Codice NUTS2 della regione | D7: Stringa | E7: Codice Eurostat NUTS2 | F7: Associare il codice Eurostat NUTS2 corrispondente alla regione. | G7: Eurostat, NUTS - NOMENCLATURE OF TERRITORIAL UNITS FOR STATISTICS. Overview, s.d., https://ec.europa.eu/eurostat/web/nuts (ultimo accesso luglio 2026).
B8: country_iso | C8: Codice ISO 3166-1 alpha-2 del Paese | D8: Stringa | E8: Codice ISO 3166-1 alpha-2 | F8: Utilizzare il codice ISO 3166-1 alpha-2 del Paese di svolgimento. Nel presente dataset il valore è sempre IT. | G8: ISO, ISO 3166. Country Codes, s.d.-a, https://www.iso.org/iso-3166-country-codes.html (ultimo accesso luglio 2026).
A9: TIME | B9: first_edition_year | C9: Anno della prima edizione del festival | D9: Intero | E9: anno / unknown | F9: Estrarre da sito ufficiale o fonti affidabili. Se non presente o non affidabile, inserire unknown. | G9: YOUROPE – The European Festival Association, ILMC, European Festival Report 2025, Drury J. (a cura di), IQ Magazine, 2026, https://yourope.org/know-how/european-festival-report-2025-out-now/ (ultimo accesso luglio 2026).
B10: festival_status | C10: Stato di attività del festival | D10: Enumerazione | E10: active / inactive / defunct / unknown | F10: - active: almeno un'edizione negli ultimi 18-24 mesi oppure annuncio ufficiale della prossima edizione (date o open call) - inactive: il festival non ha svolto edizioni negli ultimi 2 anni, ma non ha dichiarato la chiusura e i canali social/sito sono ancora online (anche se fermi) - defunct: esiste una dichiarazione ufficiale di chiusura - unknown: mancanza di dati verificabili o presenza di informazioni contrastanti | G10: YOUROPE – The European Festival Association, ILMC, European Festival Report 2025, Drury J. (a cura di), IQ Magazine, 2026, https://yourope.org/know-how/european-festival-report-2025-out-now/ (ultimo accesso luglio 2026).
B11: duration_days | C11: Durata dell'edizione più recente del festival, espressa in giorni | D11: Intero | E11: numero / unknown | F11: Si contano sia il giorno d'inizio che quello di fine (data fine - data inizio + 1) - Se il festival prevede un evento inaugurale seguito da mostre aperte al pubblico, considerare l'intero periodo di apertura - Vengono contati i giorni di durata dell'edizione più recente - unknown: se non vi sono date precise | G11: YOUROPE – The European Festival Association, ILMC, European Festival Report 2025, Drury J. (a cura di), IQ Magazine, 2026, https://yourope.org/know-how/european-festival-report-2025-out-now/ (ultimo accesso luglio 2026).
B12: recurrence | C12: Periodicità della manifestazione | D12: Enumerazione | E12: annual / biennial / mixed / unknown | F12: - annual: il festival si svolge regolarmente ogni anno - biennial: il festival si svolge regolarmente ogni due anni - mixed: il festival ha cambiato cadenza nel tempo - unknown: non vi sono sufficienti informazioni | G12: YOUROPE – The European Festival Association, ILMC, European Festival Report 2025, Drury J. (a cura di), IQ Magazine, 2026, https://yourope.org/know-how/european-festival-report-2025-out-now/ (ultimo accesso luglio 2026).
A13: DIGITAL PRESENCE | B13: website_official | C13: URL del sito web ufficiale del festival, se disponibile | D13: Stringa | E13: URL / null | F13: Inserire esclusivamente il sito web ufficiale della manifestazione. | G13: European Commission, Creative Europe 2021-2022: Monitoring report, Luxembourg, Publications Office of the European Union, 2023, https://doi.org/10.2759/561008.
B14: website_secondary | C14: URL di una fonte web secondaria di riferimento | D14: Stringa | E14: URL / null | F14: Compilare solo in assenza di un sito web ufficiale. | G14: European Commission, Creative Europe 2021-2022: Monitoring report, Luxembourg, Publications Office of the European Union, 2023, https://doi.org/10.2759/561008.
B15: website_active | C15: Stato di attività del sito web ufficiale | D15: Booleano | E15: 0 / 1 | F15: 1 = sito ufficiale raggiungibile e aggiornato 0 = sito non raggiungibile, non aggiornato o assente | G15: European Commission, Creative Europe 2021-2022: Monitoring report, Luxembourg, Publications Office of the European Union, 2023, https://doi.org/10.2759/561008.
B16: website_languages | C16: Lingue disponibili nel sito web ufficiale/secondario | D16: Enumerazione | E16: IT_EN / IT_ONLY / MULTI | F16: IT_EN: disponibile lingua inglese oltre l'italiano IT_ONLY: solo lingua italiana MULTI: disponibili altre lingue, oltre inglese e italiano | G16: European Commission, Creative Europe 2021-2022: Monitoring report, Luxembourg, Publications Office of the European Union, 2023, https://doi.org/10.2759/561008.
B17: instagram | C17: URL del profilo Instagram ufficiale | D17: Stringa | E17: URL / null | F17: Inserire solo profilo ufficiale | G17: European Commission, Creative Europe 2021-2022: Monitoring report, Luxembourg, Publications Office of the European Union, 2023, https://doi.org/10.2759/561008.
B18: facebook | C18: URL del profilo Facebook ufficiale | D18: Stringa | E18: URL / null | F18: Inserire solo profilo ufficiale | G18: European Commission, Creative Europe 2021-2022: Monitoring report, Luxembourg, Publications Office of the European Union, 2023, https://doi.org/10.2759/561008.
B19: digital_presence_score | C19: Indicatore composito del livello di presenza digitale del festival | D19: Intero | E19: da 0 a 10 compresi | F19: Website (Max 4pt): - Sito ufficiale presente: +2pt - Sito ufficiale ATTIVO (website_active = 1): +2pt Social (Max 4pt): - Instagram dedicato = +2pt - Facebook dedicato = +2pt Lingue (Max 2pt): - Multilingue = +2pt - Inglese (su sito attivo o secondario) = +1pt - Solo italiano = +0pt | G19: European Commission, Special Eurobarometer 562: Europeans’ attitudes towards culture, (Report No. SP562), Luxembourg, Publications Office of the European Union, 2025b, https://doi.org/10.2766/4514147.
A20: ORGANIZATION | B20: organizer_type | C20: Natura giuridica dell'ente organizzatore | D20: Enumerazione | E20: public / private / non_profit / unknown / mixed | F20: - public: quando l'organizzatore è un ente della Pubblica Amministrazione - non_proft: l'organizzatore è associazione culturale, di volontariato, di promozione sociale o fondazione culturale non bancaria - private: l'organizzatore è un'entità commerciale - mixed: co-organizzazione pubblico/privato - unknown: informazione non verificabile | G20: Giorgi L. (a cura di), European Arts Festivals: Cultural Pragmatics and Discursive Identity Frames (Deliverable 3.1, WP3 Main Report, Project EURO-FESTIVAL), European Commission, 2010, https://www.academia.edu/21774168/European_Arts_Festivals_Cultural_Pragmatics_and_Discursive_The_S%C3%B3nar_Festival (ultimo accesso luglio 2026).
B21: has_documented_public_funding | C21: Presenza documentata di finanziamenti pubblici al festival | D21: Booleano | E21: 0 / 1 | F21: 1: vi è evidenza di contributi economici pubblici 0: assenza di evidenze documentate di contributi economici pubblici | G21: Giorgi L. (a cura di), European Arts Festivals: Cultural Pragmatics and Discursive Identity Frames (Deliverable 3.1, WP3 Main Report, Project EURO-FESTIVAL), European Commission, 2010, https://www.academia.edu/21774168/European_Arts_Festivals_Cultural_Pragmatics_and_Discursive_The_S%C3%B3nar_Festival (ultimo accesso luglio 2026).
B22: has_international_call | C22: Presenza di una open call aperta a partecipanti internazionali | D22: Booleano | E22: 0 / 1 | F22: 1: open call aperta a fotografi di ogni nazionalità 0: open call assente oppure riservata a partecipanti italiani | G22: Giorgi L. (a cura di), European Arts Festivals: Cultural Pragmatics and Discursive Identity Frames (Deliverable 3.1, WP3 Main Report, Project EURO-FESTIVAL), European Commission, 2010, https://www.academia.edu/21774168/European_Arts_Festivals_Cultural_Pragmatics_and_Discursive_The_S%C3%B3nar_Festival (ultimo accesso luglio 2026).
B23: has_international_partners | C23: Presenza di partner o sponsor internazionali | D23: Booleano | E23: 0 / 1 | F23: 1: presenza dichiarata di partner, istituzioni, organizzazioni o sponsor internazionali. 0: non sono dichiarati partner o sponsor internazionali, solo italiani | G23: Giorgi L. (a cura di), European Arts Festivals: Cultural Pragmatics and Discursive Identity Frames (Deliverable 3.1, WP3 Main Report, Project EURO-FESTIVAL), European Commission, 2010, https://www.academia.edu/21774168/European_Arts_Festivals_Cultural_Pragmatics_and_Discursive_The_S%C3%B3nar_Festival (ultimo accesso luglio 2026).
A24: CULTURAL DOMAINS | B24: has_photography | C24: Presenza del dominio culturale fotografia nel programma del festival | D24: Booleano | E24: 0 / 1 | F24: 1 = il programma include attività fotografiche (es. mostre, installazioni, workshop, concorsi, portfolio review, incontri con fotografi o altre attività in cui la fotografia costituisce il tema centrale). 0 = la fotografia è presente esclusivamente come documentazione, comunicazione o materiale promozionale, senza una programmazione fotografica. | G24: Bína V., Chantepie P., Deroin V., Frank G., Kommel K., Kotýnek J., Robin P., ESSnet-Culture: European Statistical System Network on Culture. Final Report, Luxembourg, Ministry of Culture / European Commission (Eurostat), 2012.
B25: has_other_visual_arts | C25: Presenza di arti visive diverse dalla fotografia nel programma del festival | D25: Booleano | E25: 0 / 1 | F25: 1 = il programma include almeno un'altra disciplina delle arti visive oltre alla fotografia (es. pittura, scultura, installazione, arte contemporanea, graphic design, illustrazione, incisione). 0 = il programma comprende esclusivamente fotografia oppure elementi espositivi privi di una componente artistica autonoma. La fotografia è codificata separatamente tramite has_photography. | G25: Bína V., Chantepie P., Deroin V., Frank G., Kommel K., Kotýnek J., Robin P., ESSnet-Culture: European Statistical System Network on Culture. Final Report, Luxembourg, Ministry of Culture / European Commission (Eurostat), 2012.
B26: has_books_press | C26: Presenza di attività editoriali nel programma del festival | D26: Booleano | E26: 0 / 1 | F26: 1 = il programma include attività editoriali (es. presentazioni di libri, photobook, book fair, editoria indipendente, incontri con editori, premi dedicati ai libri fotografici). 0 = sono presenti esclusivamente cataloghi del festival, bookshop, materiali informativi o merchandising. | G26: Bína V., Chantepie P., Deroin V., Frank G., Kommel K., Kotýnek J., Robin P., ESSnet-Culture: European Statistical System Network on Culture. Final Report, Luxembourg, Ministry of Culture / European Commission (Eurostat), 2012.
A27: CULTURAL DOMAINS | B27: has_architecture_design | C27: Presenza del dominio culturale architettura e design nel programma del festival | D27: Booleano | E27: 0 / 1 | F27: 1 = il programma include attività dedicate ad architettura o design (es. mostre, workshop, conferenze, sezioni tematiche o partnership con istituzioni del settore). 0 = architettura o design costituiscono esclusivamente il contesto fisico o il soggetto di alcune fotografie, senza rappresentare un tema del programma. | G27: Bína V., Chantepie P., Deroin V., Frank G., Kommel K., Kotýnek J., Robin P., ESSnet-Culture: European Statistical System Network on Culture. Final Report, Luxembourg, Ministry of Culture / European Commission (Eurostat), 2012.
B28: has_performing_arts | C28: Presenza di arti performative nel programma del festival | D28: Booleano | E28: 0 / 1 | F28: 1 = il programma include attività performative (es. teatro, danza, performance artistiche, musica dal vivo o performance interdisciplinari). 0 = sono presenti esclusivamente accompagnamenti musicali, DJ set, eventi sociali o conferenze. | G28: Bína V., Chantepie P., Deroin V., Frank G., Kommel K., Kotýnek J., Robin P., ESSnet-Culture: European Statistical System Network on Culture. Final Report, Luxembourg, Ministry of Culture / European Commission (Eurostat), 2012.
B29: has_audiovisual_multimedia | C29: Presenza di attività appartenenti al dominio audiovisivo e multimediale nel programma del festival | D29: Booleano | E29: 0 / 1 | F29: 1 = il programma include contenuti audiovisivi o multimediali (es. cinema, documentari, videoarte, videoinstallazioni, opere multimediali, installazioni sonore, VR/AR, podcast). 0 = gli strumenti audiovisivi sono utilizzati esclusivamente come supporto tecnico o promozionale. | G29: Bína V., Chantepie P., Deroin V., Frank G., Kommel K., Kotýnek J., Robin P., ESSnet-Culture: European Statistical System Network on Culture. Final Report, Luxembourg, Ministry of Culture / European Commission (Eurostat), 2012.
A30: ACCESSIBILITY & SUSTAINABILITY | B30: venue_type | C30: Tipologia degli spazi che ospitano il festival | D30: Enumerazione | E30: museum_gallery / cultural_space / historic_site / public_space / mixed / unknown | F30: - museum_gallery: musei, gallerie d’arte, pinacoteche e spazi espositivi dedicati alla conservazione o esposizione artistica. - cultural_space: spazi culturali polifunzionali, hub creativi, centri culturali o sedi dedicate ad attività artistiche. - historic_site: luoghi di interesse storico o patrimoniale, quali castelli, palazzi storici, siti archeologici o complessi monumentali. - public_space: spazi pubblici aperti o urbani, quali piazze, strade, parchi o giardini. - mixed: presenza di più tipologie di spazi senza una categoria prevalente. - unknown: tipologia dello spazio non determinabile dalle fonti disponibili. La classificazione considera la funzione prevalente dello spazio ospitante e non esclusivamente le caratteristiche architettoniche. | G30: Alberti V., Cocco C., Consoli S., Montalto V., Panella F., Ontology Engineering to Model the European Cultural Heritage: The Case of Cultural Gems, in Yang X.-S., Sherratt R. S., Dey N., Joshi A. (a cura di), Proceedings of Eighth International Congress on Information and Communication Technology, vol. 696, Singapore, Springer Singapore, 2024, pp. 1–10, https://doi.org/10.1007/978-981-99-3236-8_1.
B31: ticket_policy | C31: Modalità di accesso economico al festival | D31: Enumerazione | E31: free / paid / mixed / unknown | F31: - free: tutte le attività sono ad accesso libero e gratuito - paid: per accedere al corpo principale delle mostre è necessario acquistare un biglietto o un pass - mixed: combinazione di contenuti gratuiti e a pagamento | G31: European Commission, Special Eurobarometer 562: Europeans’ attitudes towards culture, (Report No. SP562), Luxembourg, Publications Office of the European Union, 2025b, https://doi.org/10.2766/4514147.
B32: sustainability_claim | C32: Presenza di dichiarazioni esplicite sull'impegno ambientale del festival | D32: Booleano | E32: 0 / 1 | F32: Attribuire valore 1 solo in presenza di dichiarazioni esplicite relative alla sostenibilità ambientale (es. cambiamento climatico, biodiversità, economia circolare, mobilità sostenibile, Agenda 2030 - SDGs ambientali). | G32: YOUROPE – The European Festival Association, ILMC, European Festival Report 2025, Drury J. (a cura di), IQ Magazine, 2026, https://yourope.org/know-how/european-festival-report-2025-out-now/ (ultimo accesso luglio 2026).
A33: METADATA | B33: notes | C33: Annotazioni qualitative e informazioni aggiuntive sul record | D33: Stringa | E33: Testo libero | F33: Inserire informazioni rilevanti non rappresentabili tramite variabili strutturate, ad esempio: - sedi secondarie; - carattere itinerante del festival; - cambiamenti organizzativi; - informazioni ambigue o non verificabili; - eccezioni metodologiche. | G33: -
B34: record_last_updated | C34: Data dell'ultima revisione del record | D34: Data | E34: Data nel formato ISO 8601: YYYY-MM-DD | F34: Indicare la data dell'ultimo controllo o aggiornamento significativo del record. | G34: -

Sheet Locations
A1: city | B1: city_geonames_name | C1: city_istat_code | D1: city_geonames_id | E1: region | F1: regione_nuts | G1: country | H1: country_iso
A2: Agliè | C2: 1001 | D2: {=IF(A2:A7894="","",XLOOKUP(A2:A7894,GEONAMES!A:A,GEONAMES!B:B,""))} | E2: Piemonte | F2: ITC1
A3: Airasca | C3: 1002 | D3: 3183380 | E3: Piemonte | F3: ITC1
A4: Ala di Stura | C4: 1003 | D4: 3183371 | E4: Piemonte | F4: ITC1
A5: Albiano d'Ivrea | C5: 1004 | D5: 3183322 | E5: Piemonte | F5: ITC1
A6: Almese | C6: 1006 | E6: Piemonte | F6: ITC1
A7: Alpette | C7: 1007 | D7: 3183198 | E7: Piemonte | F7: ITC1
A8: Alpignano | C8: 1008 | D8: 3183187 | E8: Piemonte | F8: ITC1
A9: Andezeno | C9: 1009 | D9: 3183081 | E9: Piemonte | F9: ITC1
A10: Andrate | C10: 1010 | D10: 3183077 | E10: Piemonte | F10: ITC1
A11: Angrogna | C11: 1011 | D11: 6535055 | E11: Piemonte | F11: ITC1
A12: Arignano | C12: 1012 | D12: 3182846 | E12: Piemonte | F12: ITC1
A13: Avigliana | C13: 1013 | D13: 3182634 | E13: Piemonte | F13: ITC1
A14: Azeglio | C14: 1014 | D14: 3182615 | E14: Piemonte | F14: ITC1
A15: Bairo | C15: 1015 | D15: 6535053 | E15: Piemonte | F15: ITC1
A16: Balangero | C16: 1016 | D16: 3182466 | E16: Piemonte | F16: ITC1
A17: Baldissero Canavese | C17: 1017 | D17: 6535054 | E17: Piemonte | F17: ITC1
A18: Baldissero Torinese | C18: 1018 | D18: 3182461 | E18: Piemonte | F18: ITC1
... A48: Cambiano | C48: 1048 | D48: 3181111 | E48: Piemonte | F48: ITC1
A49: Campiglione Fenile | C49: 1049 | E49: Piemonte | F49: ITC1
A50: Candia Canavese | C50: 1050 | D50: 3180868 | E50: Piemonte | F50: ITC1
A51: Candiolo | C51: 1051 | D51: 3180861 | E51: Piemonte | F51: ITC1
A52: Canischio | C52: 1052 | D52: 3180835 | E52: Piemonte | F52: ITC1
A53: Cantalupa | C53: 1053 | D53: 6535265 | E53: Piemonte | F53: ITC1
A54: Cantoira | C54: 1054 | D54: 3180766 | E54: Piemonte | F54: ITC1
A55: Caprie | C55: 1055 | D55: 3180621 | E55: Piemonte | F55: ITC1
A56: Caravino | C56: 1056 | D56: 3180578 | E56: Piemonte | F56: ITC1
A57: Carema | C57: 1057 | D57: 3180531 | E57: Piemonte | F57: ITC1
A58: Carignano | C58: 1058 | D58: 3180511 | E58: Piemonte | F58: ITC1
A59: Carmagnola | C59: 1059 | D59: 3180496 | E59: Piemonte | F59: ITC1
A60: Casalborgone | C60: 1060 | D60: 3180245 | E60: Piemonte | F60: ITC1
A61: Cascinette d'Ivrea | C61: 1061 | D61: 3179958 | E61: Piemonte | F61: ITC1
... A85: Cinzano | C85: 1085 | D85: 3178662 | E85: Piemonte | F85: ITC1
A86: Ciriè | C86: 1086 | E86: Piemonte | F86: ITC1
A87: Claviere | C87: 1087 | D87: 3178550 | E87: Piemonte | F87: ITC1
A88: Coassolo Torinese | C88: 1088 | D88: 6534296 | E88: Piemonte | F88: ITC1
A89: Coazze | C89: 1089 | D89: 3178536 | E89: Piemonte | F89: ITC1
A90: Collegno | C90: 1090 | D90: 3178388 | E90: Piemonte | F90: ITC1
A91: Colleretto Castelnuovo | C91: 1091 | D91: 6535270 | E91: Piemonte | F91: ITC1
A92: Colleretto Giacosa | C92: 1092 | D92: 6535271 | E92: Piemonte | F92: ITC1
...

Sheet GEONAMES
A1: city | B1: geonames_id
A2: Corigliano-Rossano | B2: 12032199
A3: Neive | B3: 6536417
A4: Alpago | B4: 11287678
A5: Fiumicello Villa Vicentina | B5: 12032187
A6: Colognole | B6: 781059
A7: Casale Sant'Antonio | B7: 781060
A8: Zungti | B8: 2522676
A9: Zumpano | B9: 2522677
A10: Zona | B10: 2522679
A11: Zinga | B11: 2522681
A12: Zerfaliu | B12: 2522683
A13: Zeppara | B13: 2522684
... A32046: Zucchi | B32046: 8960423
A32047: FALSE | B32047: 8960424
A32048: Casalini | B32048: 8960425
A32049: Case Frasson | B32049: 8960426
A32050: Bocca di Serra | B32050: 8960427
A32051: Guizza | B32051: 8960428
A32052: Bobbato | B32052: 8960429
A32053: Volpato | B32053: 8960430
A32054: Rialto | B32054: 8960431
A32055: Zona Buzzaccarina | B32055: 8960432
A32056: Monte Grappa | B32056: 8960433
A32057: Della Croce | B32057: 8960434
A32058: Santa Lucia | B32058: 8960435
A32059: Grottarole | B32059: 8960436
... A58259: Selvavetere | B58259: 13665314

Sheet SCARTATI
A1: FEST000033 | B1: miart | C1: Milano | D1: {=XLOOKUP(C1,Locations!A:A,Locations!D:D,"")} -> 6951411 | E1: {=XLOOKUP(C1,Locations!A:A,Locations!E:E,"")} -> Lombardia | F1: {=XLOOKUP(C1,Locations!A:A,Locations!F:F,"")} -> ITC4 | G1: IT | H1: 1996 | J1: 3 giorni | K1: annual | L1: http://www.miart.it/ | P1: https://www.instagram.com/miartmilano/?hl=it | Q1: https://www.facebook.com/miart.milano/?locale=it_IT | R1: 6 | X1: 1
A2: FEST000037 | B2: Genius Loci | C2: Latina | D2: {=XLOOKUP(C2,Locations!A:A,Locations!D:D,"")} -> 3175058 | E2: {=XLOOKUP(C2,Locations!A:A,Locations!E:E,"")} -> Lazio | F2: {=XLOOKUP(C2,Locations!A:A,Locations!F:F,"")} -> ITI4 | G2: IT | H2: 2025 | J2: 7 giorni | K2: annual | M2: https://openhublazio.it/it/open-calls/genius-loci | R2: 0 | X2: 1
A3: FEST000039 | B3: Pulcinella Film Fest - Festival della Commedia | C3: Acerra | D3: {=XLOOKUP(C3,Locations!A:A,Locations!D:D,"")} -> 3183541 | E3: {=XLOOKUP(C3,Locations!A:A,Locations!E:E,"")} -> Campania | F3: {=XLOOKUP(C3,Locations!A:A,Locations!F:F,"")} -> ITF3 | G3: IT | H3: 2018 | J3: 7 giorni | K3: annual | L3: https://www.festivaldellacommedia.it/it/ | P3: https://www.instagram.com/festivaldellacommedia/ | Q3: https://www.facebook.com/festivaldellacommedia/?locale=it_IT | R3: 6 | X3: 1
A4: FEST000041 | B4: Festival N*Stories | C4: Altamura | D4: {=XLOOKUP(C4,Locations!A:A,Locations!D:D,"")} -> 3183178 | E4: {=XLOOKUP(C4,Locations!A:A,Locations!E:E,"")} -> Puglia | F4: {=XLOOKUP(C4,Locations!A:A,Locations!F:F,"")} -> ITF4 | G4: IT | H4: 2018 | J4: 7 giorni | K4: annual | L4: https://www.festivalnstories.it/ | P4: https://www.instagram.com/festivalnstories/ | Q4: https://www.facebook.com/festivalnstories | R4: 6 | X4: 1
A5: FEST000042 | B5: Festival della Comunicazione e del Cinema Archeologico | C5: Licodia Eubea | D5: {=XLOOKUP(C5,Locations!A:A,Locations!D:D,"")} -> 2524392 | E5: {=XLOOKUP(C5,Locations!A:A,Locations!E:E,"")} -> Sicilia | F5: {=XLOOKUP(C5,Locations!A:A,Locations!F:F,"")} -> ITG1 | G5: IT | H5: 2011 | J5: 7 giorni | K5: annual | L5: https://www.rassegnalicodia.it/ | P5: https://instagram.com/festivallicodiaeubea | Q5: https://www.facebook.com/festivallicodiaeubea | R5: 6 | X5: 1
A6: FEST000045 | B6: Alcart Festival | C6: Alcamo | D6: {=XLOOKUP(C6,Locations!A:A,Locations!D:D,"")} -> 2525755 | E6: {=XLOOKUP(C6,Locations!A:A,Locations!E:E,"")} -> Sicilia | F6: {=XLOOKUP(C6,Locations!A:A,Locations!F:F,"")} -> ITG1 | G6: IT | H6: 2023 | J6: 5 giorni | K6: annual | M6: https://www.comune.alcamo.tp.it/it/eventi/alcart | P6: https://www.instagram.com/alcartfestival/ | Q6: https://www.facebook.com/alcartfestival/?locale=it_IT | R6: 4 | X6: 1
A7: FEST000046 | B7: AbitiAmo la Terra | C7: Piossasco | D7: {=XLOOKUP(C7,Locations!A:A,Locations!D:D,"")} -> 3170659 | E7: {=XLOOKUP(C7,Locations!A:A,Locations!E:E,"")} -> Piemonte | F7: {=XLOOKUP(C7,Locations!A:A,Locations!F:F,"")} -> ITC1 | G7: IT | H7: 2014 | J7: 6 giorni | K7: annual | M7: https://www.amicidijoaquimgomes.it/2025/05/24/abitiamo-la-terra-festa-brasiliana-2025/ | R7: 0 | X7: 1
A8: FEST000047 | B8: Between Land and Sea | C8: Palermo | D8: {=XLOOKUP(C8,Locations!A:A,Locations!D:D,"")} -> 2523920 | E8: {=XLOOKUP(C8,Locations!A:A,Locations!E:E,"")} -> Sicilia | F8: {=XLOOKUP(C8,Locations!A:A,Locations!F:F,"")} -> ITG1 | G8: IT | H8: 2021 | J8: 4 giorni | K8: annual | L8: https://www.betweenlandandsea.org/ | P8: https://www.instagram.com/studio_rizoma_/ | Q8: https://www.facebook.com/studiorizomapa | R8: 6 | X8: 1
A9: FEST000050 | B9: SI Fest Off | C9: Verghereto | D9: {=XLOOKUP(C9,Locations!A:A,Locations!D:D,"")} -> 3164550 | E9: {=XLOOKUP(C9,Locations!A:A,Locations!E:E,"")} -> Emilia-Romagna | F9: {=XLOOKUP(C9,Locations!A:A,Locations!F:F,"")} -> ITH5 | G9: IT | H9: 2009 | J9: 3 giorni | K9: annual | M9: https://www.sifest.it/it/si-fest-off/archivio-off.html | Q9: https://www.facebook.com/offsavignano/?locale=it_IT | R9: 2 | X9: 1
A10: FEST000051 | B10: Milano Photo Week | C10: Milano | D10: {=XLOOKUP(C10,Locations!A:A,Locations!D:D,"")} -> 6951411 | E10: {=XLOOKUP(C10,Locations!A:A,Locations!E:E,"")} -> Lombardia | F10: {=XLOOKUP(C10,Locations!A:A,Locations!F:F,"")} -> ITC4 | G10: IT | H10: 2017 | J10: 7 giorni | K10: annual | M10: https://bnl.it/it/Scopri-BNL/Partnership-ed-Eventi/Arte-e-Cultura/Mostre-Fotografiche/Milano-Photo-Week | Q10: https://www.facebook.com/milanophotoweek/?locale=it_IT | R10: 2 | X10: 1
A11: FEST000063 | B11: Artlab Eyeland | C11: Taranto | D11: {=XLOOKUP(C11,Locations!A:A,Locations!D:D,"")} -> 3165926 | E11: {=XLOOKUP(C11,Locations!A:A,Locations!E:E,"")} -> Puglia | F11: {=XLOOKUP(C11,Locations!A:A,Locations!F:F,"")} -> ITF4 | G11: IT | H11: 2023 | J11: 1 mese | K11: annual | L11: https://www.artlabeyeland.it/ | P11: https://www.instagram.com/artlab_eyeland/ | Q11: https://www.facebook.com/profile.php?id=100091904272457 | R11: 6 | X11: 1
A12: FEST000065 | B12: Ortigia Contemporanea | C12: Siracusa | D12: {=XLOOKUP(C12,Locations!A:A,Locations!D:D,"")} -> 2523083 | E12: {=XLOOKUP(C12,Locations!A:A,Locations!E:E,"")} -> Sicilia | F12: {=XLOOKUP(C12,Locations!A:A,Locations!F:F,"")} -> ITG1 | G12: IT | H12: 2024 | J12: 2 weekend | K12: annual | M12: https://www.arte.it/calendario-arte/siracusa/mostra-ortigia-contemporanea-i-festival-internazionale-d-arte-contemporanea-in-sicilia-97895 | P12: https://www.instagram.com/ortigiacontemporanea/ | Q12: https://www.facebook.com/ortigiacontemporanea/ | R12: 4 | X12: 1
A13: FEST000068 | B13: Arte Fiera | C13: Bologna | D13: {=XLOOKUP(C13,Locations!A:A,Locations!D:D,"")} -> 3181928 | E13: {=XLOOKUP(C13,Locations!A:A,Locations!E:E,"")} -> Emilia-Romagna | F13: {=XLOOKUP(C13,Locations!A:A,Locations!F:F,"")} -> ITH5 | G13: IT | H13: 1974 | J13: 3 giorni | K13: annual | L13: https://www.artefiera.it/home/776.html | P13: https://www.instagram.com/artefiera_bologna/ | Q13: http://www.facebook.com/artefiera/ | R13: 6 | X13: 1
A14: FEST000072 | B14: RoRegeneration | C14: Rovigo | D14: {=XLOOKUP(C14,Locations!A:A,Locations!D:D,"")} -> 3168843 | E14: {=XLOOKUP(C14,Locations!A:A,Locations!E:E,"")} -> Veneto | F14: {=XLOOKUP(C14,Locations!A:A,Locations!F:F,"")} -> ITH3 | G14: IT | H14: 2021 | J14: 7 giorni | K14: annual | M14: https://www.rovigoinfocitta.it/roregeneration-il-festival-della-rigenerazione-urbana-esplora-nuove-forme-d%E2%80%99arte/ | R14: 0 | X14: 1
A15: FEST000007 | B15: Contemporanea Film Festival | C15: Torino | D15: {=XLOOKUP(C15,Locations!A:A,Locations!D:D,"")} -> 8980539 | E15: {=XLOOKUP(C15,Locations!A:A,Locations!E:E,"")} -> Piemonte | F15: {=XLOOKUP(C15,Locations!A:A,Locations!F:F,"")} -> ITC1 | G15: IT | H15: 2022 | I15: active | J15: 5 | K15: annual | L15: https://www.contemporaneafilmfestival.com/ | N15: 1 | O15: IT_ONLY | P15: https://www.instagram.com/contemporanea_festival/ | Q15: https://www.facebook.com/ContemporaneaFilmFestival | R15: 8 | S15: non-profit | T15: 1 | W15: 1 | X15: 1 | Y15: 1 | Z15: 0 | AA15: 0 | AB15: 0 | AC15: 0 | AD15: 1 | AE15: mixed | AF15: mixed | AG15: 0
A16: FEST000010 | B16: Murgiafest | C16: Santeramo in Colle | D16: {=XLOOKUP(C16,Locations!A:A,Locations!D:D,"")} -> 3167327 | E16: {=XLOOKUP(C16,Locations!A:A,Locations!E:E,"")} -> Puglia | F16: {=XLOOKUP(C16,Locations!A:A,Locations!F:F,"")} -> ITF4 | G16: IT | H16: 2010 | I16: active | J16: 3 | K16: annual | M16: https://arcistandby.com/murgiafest-main/ | N16: 0 | O16: IT_ONLY | R16: 0 | S16: non-profit | T16: 0 | W16: 0 | X16: 1 | Y16: 1 | Z16: 0 | AA16: 0 | AB16: 0 | AC16: 1 | AD16: 1 | AE16: public_space | AF16: free | AG16: 1
A17: FEST000016 | B17: Alba e tramonto festival | C17: Castiglione d'Orcia | D17: {=XLOOKUP(C17,Locations!A:A,Locations!D:D,"")} -> 3179411 | E17: {=XLOOKUP(C17,Locations!A:A,Locations!E:E,"")} -> Toscana | F17: {=XLOOKUP(C17,Locations!A:A,Locations!F:F,"")} -> ITI1 | G17: IT | H17: 2020 | I17: active | J17: 15 | K17: annual | L17: https://www.albaetramontofestival.it/ | N17: 1 | O17: IT_ONLY | P17: https://www.instagram.com/albaetramontofestival/ | R17: 6 | S17: non-profit | T17: 1 | W17: 0 | X17: 1 | Y17: 1 | Z17: 1 | AA17: 1 | AB17: 1 | AC17: 1 | AD17: 0 | AE17: public_space | AF17: free | AG17: 1
A18: FEST000001 | B18: Xenos - Festival di performance | C18: Siena | D18: {=XLOOKUP(C18,Locations!A:A,Locations!D:D,"")} -> 3166548 | E18: {=XLOOKUP(C18,Locations!A:A,Locations!E:E,"")} -> Toscana | F18: {=XLOOKUP(C18,Locations!A:A,Locations!F:F,"")} -> ITI1 | G18: IT | H18: 2024 | I18: active | J18: 4 | K18: annual | L18: null | M18: https://www.santamariadellascala.com/eventi/xenos-festival-di-performance | N18: 0 | O18: MULTI | P18: null | Q18: null | R18: {=IF(A18:A1000="","",IF(L18:L1000<>"",2,0)+IF(N18:N1000=1,2,0)+IF(O18:O1000="IT_EN",1,0)+IF(O18:O1000="MULTI",2,0)+IF(P18:P1000<>"",2,0)+IF(Q18:Q1000<>"",2,0))} -> #REF! | S18: non-profit | T18: 1 | W18: 1 | X18: 1 | Y18: 1 | Z18: 0 | AA18: 1 | AB18: 0 | AC18: 1 | AD18: 1 | AE18: museum_gallery | AF18: mixed | AG18: 0
A19: FEST000022 | B19: Posidonia Green Festival | C19: Bogliasco | D19: {=XLOOKUP(C19,Locations!A:A,Locations!D:D,"")} -> 3181943 | E19: {=XLOOKUP(C19,Locations!A:A,Locations!E:E,"")} -> Liguria | F19: {=XLOOKUP(C19,Locations!A:A,Locations!F:F,"")} -> ITC3 | G19: IT | H19: 2008 | I19: active | J19: 2 | K19: annual | L19: https://posidoniagreenfestival.com/ | M19: null | N19: 1 | O19: MULTI | P19: https://www.instagram.com/posidoniagreenfestival/ | Q19: https://www.facebook.com/PosidoniaFestivalGreen/ | R19: 10 | S19: non-profit | T19: 0 | U19: 0 | V19: 1 | X19: 1 | Y19: 1 | Z19: 0 | AB19: 0 | AC19: 1 | AD19: 1 | AE19: public_space | AF19: free | AG19: 1 | AH19: In altre date si svolge anche a Barcellona.
A20: FEST000023 | B20: Sempre Più Fuori Festival | C20: Roma | D20: {=XLOOKUP(C20,Locations!A:A,Locations!D:D,"")} -> 8957247 | E20: {=XLOOKUP(C20,Locations!A:A,Locations!E:E,"")} -> Lazio | F20: {=XLOOKUP(C20,Locations!A:A,Locations!F:F,"")} -> ITI4 | G20: IT | H20: unknown | I20: active | J20: 12 | K20: annual | L20: https://www.semprepiufuori.it/ | M20: null | N20: 1 | O20: IT_ONLY | P20: https://www.instagram.com/semprepiufuori/ | Q20: https://www.facebook.com/semprepiufuorifestival | R20: 8 | S20: non-profit | T20: 1 | U20: 0 | V20: 1 | X20: 1 | Y20: 1 | Z20: 0 | AB20: 0 | AC20: 1 | AD20: 1 | AE20: mixed | AF20: mixed | AG20: 0
A21: FEST000019 | B21: Paradiso Film Fest | C21: Palazzo Adriano | D21: {=XLOOKUP(C21,Locations!A:A,Locations!D:D,"")} -> 2523925 | E21: {=XLOOKUP(C21,Locations!A:A,Locations!E:E,"")} -> Sicilia | F21: {=XLOOKUP(C21,Locations!A:A,Locations!F:F,"")} -> ITG1 | G21: IT | H21: 2020 | I21: active | J21: 3 | K21: annual | L21: https://www.paradisofilmfest.com/ | M21: null | N21: 1 | O21: IT_EN | P21: https://www.instagram.com/paradiso_film_fest/ | Q21: https://www.facebook.com/ParadisoFilmFest | R21: 9 | S21: non-profit | T21: 1 | W21: 1 | X21: 1 | Y21: 1 | Z21: 1 | AA21: 1 | AB21: 1 | AC21: 1 | AD21: 1 | AE21: 0 | AG21: 46227
A22: FEST000020 | B22: AESON Festival | C22: Fiumicello Villa Vicentina | D22: {=XLOOKUP(C22,Locations!A:A,Locations!D:D,"")} -> 12032187 | E22: {=XLOOKUP(C22,Locations!A:A,Locations!E:E,"")} -> Friuli-Venezia Giulia | F22: {=XLOOKUP(C22,Locations!A:A,Locations!F:F,"")} -> ITH4 | G22: IT | H22: 2008 | I22: active | J22: 4 | K22: annual | L22: https://www.aeson.it/ | M22: null | N22: 1 | O22: IT_ONLY | P22: https://www.instagram.com/aesonfestival/ | Q22: https://www.facebook.com/aeson.artinellanatura | R22: 8 | S22: non-profit | T22: 1 | W22: 1 | X22: 1 | Y22: 1 | Z22: 0 | AB22: 1 | AC22: 1 | AD22: 1 | AE22: public_space | AF22: free | AG22: 1 | AI22: 46227
